Traceback (most recent call last):
  File "/usr/share/miniconda3/envs/elwah_env/lib/python3.10/site-packages/jupyter_cache/executors/utils.py", line 51, in single_nb_execution
    executenb(
  File "/usr/share/miniconda3/envs/elwah_env/lib/python3.10/site-packages/nbclient/client.py", line 1204, in execute
    return NotebookClient(nb=nb, resources=resources, km=km, **kwargs).execute()
  File "/usr/share/miniconda3/envs/elwah_env/lib/python3.10/site-packages/nbclient/util.py", line 84, in wrapped
    return just_run(coro(*args, **kwargs))
  File "/usr/share/miniconda3/envs/elwah_env/lib/python3.10/site-packages/nbclient/util.py", line 62, in just_run
    return loop.run_until_complete(coro)
  File "/usr/share/miniconda3/envs/elwah_env/lib/python3.10/asyncio/base_events.py", line 646, in run_until_complete
    return future.result()
  File "/usr/share/miniconda3/envs/elwah_env/lib/python3.10/site-packages/nbclient/client.py", line 663, in async_execute
    await self.async_execute_cell(
  File "/usr/share/miniconda3/envs/elwah_env/lib/python3.10/site-packages/nbclient/client.py", line 965, in async_execute_cell
    await self._check_raise_for_error(cell, cell_index, exec_reply)
  File "/usr/share/miniconda3/envs/elwah_env/lib/python3.10/site-packages/nbclient/client.py", line 862, in _check_raise_for_error
    raise CellExecutionError.from_cell_and_msg(cell, exec_reply_content)
nbclient.exceptions.CellExecutionError: An error occurred while executing the following cell:
------------------
rgb_images = []
for x in range(num_images):
  image_data = im.fromarray(raw_images[:,:,x])
  rgb_images.append(image_data)
  image_data.save(f"../out/airborne_{x+1}.png")

display(rgb_images[10])
------------------

[0;31m---------------------------------------------------------------------------[0m
[0;31mFileNotFoundError[0m                         Traceback (most recent call last)
Cell [0;32mIn [6], line 5[0m
[1;32m      3[0m   image_data [38;5;241m=[39m im[38;5;241m.[39mfromarray(raw_images[:,:,x])
[1;32m      4[0m   rgb_images[38;5;241m.[39mappend(image_data)
[0;32m----> 5[0m   [43mimage_data[49m[38;5;241;43m.[39;49m[43msave[49m[43m([49m[38;5;124;43mf[39;49m[38;5;124;43m"[39;49m[38;5;124;43m../out/airborne_[39;49m[38;5;132;43;01m{[39;49;00m[43mx[49m[38;5;241;43m+[39;49m[38;5;241;43m1[39;49m[38;5;132;43;01m}[39;49;00m[38;5;124;43m.png[39;49m[38;5;124;43m"[39;49m[43m)[49m
[1;32m      7[0m display(rgb_images[[38;5;241m10[39m])

File [0;32m/usr/share/miniconda3/envs/elwah_env/lib/python3.10/site-packages/PIL/Image.py:2317[0m, in [0;36mImage.save[0;34m(self, fp, format, **params)[0m
[1;32m   2315[0m         fp [38;5;241m=[39m builtins[38;5;241m.[39mopen(filename, [38;5;124m"[39m[38;5;124mr+b[39m[38;5;124m"[39m)
[1;32m   2316[0m     [38;5;28;01melse[39;00m:
[0;32m-> 2317[0m         fp [38;5;241m=[39m [43mbuiltins[49m[38;5;241;43m.[39;49m[43mopen[49m[43m([49m[43mfilename[49m[43m,[49m[43m [49m[38;5;124;43m"[39;49m[38;5;124;43mw+b[39;49m[38;5;124;43m"[39;49m[43m)[49m
[1;32m   2319[0m [38;5;28;01mtry[39;00m:
[1;32m   2320[0m     save_handler([38;5;28mself[39m, fp, filename)

[0;31mFileNotFoundError[0m: [Errno 2] No such file or directory: '../out/airborne_1.png'
FileNotFoundError: [Errno 2] No such file or directory: '../out/airborne_1.png'

